<?xml version="1.0" ?>
<robot name="hunter">
  <link name="base_link"/>
  <joint name="chassis_joint" type="fixed">
    <parent link="base_link"/>
    <child link="chassis"/>
    <origin rpy="0 0 0" xyz="0 0 0.37"/>
  </joint>
  <link name="chassis">
    <visual>
      <origin rpy="0 0 0" xyz="0 0 0"/>
      <geometry>
        <mesh filename="file:///home/ibrahim/aoc/hunter/install/hunter_description/share/hunter_description/meshes/chassis.dae"/>
      </geometry>
    </visual>
    <collision>
      <origin rpy="0 0 0" xyz="0 0 0"/>
      <geometry>
        <mesh filename="file:///home/ibrahim/aoc/hunter/install/hunter_description/share/hunter_description/meshes/chassis.dae"/>
      </geometry>
    </collision>
    <inertial>
      <origin rpy="0 0 0" xyz="0.0266989327622036 0.000409203500587652 -0.135901124750884"/>
      <mass value="72"/>
      <inertia ixx="0.0332370959804736" ixy="-1.013150489971E-06" ixz="-0.00188859201421112" iyy="0.111072002332437" iyz="-5.13308150598312E-07" izz="0.12660862809283"/>
    </inertial>
  </link>
  <link name="rear_left_wheel">
    <visual>
      <origin rpy="0 0 0" xyz="0 0 0"/>
      <geometry>
        <mesh filename="file:///home/ibrahim/aoc/hunter/install/hunter_description/share/hunter_description/meshes/rear_left_wheel.dae"/>
      </geometry>
    </visual>
    <collision>
      <origin rpy="0 0 0" xyz="0 0 0"/>
      <geometry>
        <mesh filename="file:///home/ibrahim/aoc/hunter/install/hunter_description/share/hunter_description/meshes/rear_left_wheel.dae"/>
      </geometry>
    </collision>
    <inertial>
      <origin rpy="0 0 0" xyz="-6.5774E-06 2.0242E-05 -0.0096386"/>
      <mass value="7.0"/>
      <inertia ixx="0.063724" ixy="0" ixz="0" iyy="0.063724" iyz="0" izz="0.11072"/>
    </inertial>
  </link>
  <joint name="rear_left_wheel_joint" type="continuous">
    <parent link="chassis"/>
    <child link="rear_left_wheel"/>
    <origin rpy="1.5707963267948966 0 0" xyz="-0.28 0.2925 -0.19558"/>
    <axis xyz="0 0 -1"/>
    <dynamics damping="0.2" friction="15"/>
    <limit effort="10.0" velocity="10.0"/>
  </joint>
  <link name="rear_right_wheel">
    <visual>
      <origin rpy="0 0 0" xyz="0 0 0"/>
      <geometry>
        <mesh filename="file:///home/ibrahim/aoc/hunter/install/hunter_description/share/hunter_description/meshes/rear_right_wheel.dae"/>
      </geometry>
    </visual>
    <collision>
      <origin rpy="0 0 0" xyz="0 0 0"/>
      <geometry>
        <mesh filename="file:///home/ibrahim/aoc/hunter/install/hunter_description/share/hunter_description/meshes/rear_right_wheel.dae"/>
      </geometry>
    </collision>
    <inertial>
      <origin rpy="0 0 0" xyz="-6.5774E-06 2.0242E-05 -0.0096386"/>
      <mass value="7.0"/>
      <inertia ixx="0.063724" ixy="0" ixz="0" iyy="0.063724" iyz="0" izz="0.11072"/>
    </inertial>
  </link>
  <joint name="rear_right_wheel_joint" type="continuous">
    <parent link="chassis"/>
    <child link="rear_right_wheel"/>
    <origin rpy="1.5707963267948966 0 0" xyz="-0.28 -0.2925 -0.19558"/>
    <axis xyz="0.0 0.0 -1.0"/>
    <dynamics damping="0.2" friction="15"/>
    <limit effort="10.0" velocity="10.0"/>
  </joint>
  <link name="front_left_steering_link">
    <visual>
      <origin rpy="0 0 0" xyz="0 0 0"/>
      <geometry>
        <cylinder length="0.01" radius="0.01"/>
      </geometry>
      <material name="invisible">
        <color rgba="0.0 0.0 0.0 0.0"/>
      </material>
    </visual>
    <inertial>
      <origin rpy="0 0 0" xyz="0 0 0"/>
      <mass value="0.005"/>
      <inertia ixx="0.1" ixy="0" ixz="0" iyy="0.1" iyz="0" izz="0.1"/>
    </inertial>
  </link>
  <joint name="front_left_steering_joint" type="continuous">
    <parent link="chassis"/>
    <child link="front_left_steering_link"/>
    <origin rpy="1.5707963267948966 0 0" xyz="0.37142 0.2925 -0.19558"/>
    <axis xyz="0 1 0"/>
    <!-- <limit effort="10.0" lower="-0.461" upper="0.461" velocity="0"/> -->
    <dynamics damping="0.2"/>
  </joint>
  <link name="front_left_wheel">
    <visual>
      <origin rpy="0 0 0" xyz="0 0 0"/>
      <geometry>
        <mesh filename="file:///home/ibrahim/aoc/hunter/install/hunter_description/share/hunter_description/meshes/front_left_wheel.dae"/>
      </geometry>
    </visual>
    <collision>
      <origin rpy="0 0 0" xyz="0 0 0"/>
      <geometry>
        <mesh filename="file:///home/ibrahim/aoc/hunter/install/hunter_description/share/hunter_description/meshes/front_left_wheel.dae"/>
      </geometry>
    </collision>
    <inertial>
      <origin rpy="0 0 0" xyz="-6.5774E-06 2.0242E-05 -0.0096386"/>
      <mass value="7.0"/>
      <inertia ixx="0.063724" ixy="0" ixz="0" iyy="0.063724" iyz="0" izz="0.11072"/>
    </inertial>
  </link>
  <joint name="front_left_wheel_joint" type="continuous">
    <parent link="front_left_steering_link"/>
    <child link="front_left_wheel"/>
    <origin rpy="0 0 0" xyz="0 0 0"/>
    <axis xyz="0 0 -1"/>
  </joint>
  <link name="front_right_steering_link">
    <visual>
      <origin rpy="0 0 0" xyz="0 0 0"/>
      <geometry>
        <cylinder length="0.01" radius="0.01"/>
      </geometry>
      <material name="invisible">
        <color rgba="0.0 0.0 0.0 0.0"/>
      </material>
    </visual>
    <inertial>
      <origin rpy="0 0 0" xyz="0 0 0"/>
      <mass value="0.005"/>
      <inertia ixx="0.1" ixy="0" ixz="0" iyy="0.1" iyz="0" izz="0.1"/>
    </inertial>
  </link>
  <joint name="front_right_steering_joint" type="continuous">
    <parent link="chassis"/>
    <child link="front_right_steering_link"/>
    <origin rpy="1.5707963267948966 0 0" xyz="0.37142  -0.2925 -0.19558"/>
    <axis xyz="0 1 0"/>
    <!-- <limit effort="10.0" lower="-0.461" upper="0.461" velocity="0"/> -->
    <dynamics damping="0.2"/>
  </joint>
  <link name="front_right_wheel">
    <visual>
      <origin rpy="0 0 0" xyz="0 0 0"/>
      <geometry>
        <mesh filename="file:///home/ibrahim/aoc/hunter/install/hunter_description/share/hunter_description/meshes/front_right_wheel.dae"/>
      </geometry>
    </visual>
    <collision>
      <origin rpy="0 0 0" xyz="0 0 0"/>
      <geometry>
        <mesh filename="file:///home/ibrahim/aoc/hunter/install/hunter_description/share/hunter_description/meshes/front_right_wheel.dae"/>
      </geometry>
    </collision>
    <inertial>
      <origin rpy="0 0 0" xyz="-6.5774E-06 2.0242E-05 -0.0096386"/>
      <mass value="7.0"/>
      <inertia ixx="0.063724" ixy="0" ixz="0" iyy="0.063724" iyz="0" izz="0.11072"/>
    </inertial>
  </link>
  <joint name="front_right_wheel_joint" type="continuous">
    <parent link="front_right_steering_link"/>
    <child link="front_right_wheel"/>
    <origin rpy="0 0 0" xyz="0 0 0"/>
    <axis xyz="0 0 -1"/>
  </joint>
  <ros2_control name="GazeboSystem" type="system">
    <hardware>
      <plugin>gazebo_ros2_control/GazeboSystem</plugin>
    </hardware>
    <joint name="front_left_steering_joint">
      <command_interface name="position"/>
      <state_interface name="position"/>
    </joint>
    <joint name="front_right_steering_joint">
      <command_interface name="position"/>
      <state_interface name="position"/>
    </joint>
    <joint name="front_right_wheel_joint">
      <!-- <command_interface name="velocity"/> -->
      <state_interface name="velocity"/>
      <state_interface name="position"/>
    </joint>
    <joint name="front_left_wheel_joint">
      <!-- <command_interface name="velocity"/> -->
      <state_interface name="velocity"/>
      <state_interface name="position"/>
    </joint>    
    <joint name="rear_right_wheel_joint">
      <command_interface name="velocity"/>
      <state_interface name="velocity"/>
      <state_interface name="position"/>
    </joint>
    <joint name="rear_left_wheel_joint">
      <command_interface name="velocity"/>
      <state_interface name="velocity"/>
      <state_interface name="position"/>
    </joint>
  </ros2_control>
  <gazebo>
    <plugin filename="libgazebo_ros2_control.so" name="gazebo_ros2_control">
      <parameters>/home/ibrahim/aoc/hunter/install/hunter_description/share/hunter_description/config/ackermann_controller.yaml</parameters>
    </plugin>
  </gazebo>
</robot>
