<?xml version="1.0"?>

<robot xmlns:xacro="http://ros.org/wiki/xacro" name="hunter_wheel">

  <xacro:macro name="hunter_wheel" params="wheel_prefix x y z roll:=0.0 pitch:=0.0 yaw:=0.0 is_sim:=true">
    <link name="${wheel_prefix}_wheel">
      <inertial>
        <mass value="4.71327697475564" />
        <origin xyz="0 0 0" />
        <inertia  ixx="0.110728822762987" ixy="-2.65377659117968E-08" ixz="-5.98702902432139E-08" iyy="0.0637297556516867" iyz="2.53851903686626E-07" izz="0.0637296696516031" />
      </inertial>
      <visual>
        <origin xyz="0 0 0" rpy="0 0 0" />
        <geometry>
          <mesh filename="file://$(find hunter_description)/meshes/wheel.dae" />
        </geometry>
      </visual>
      <collision>
        <origin xyz="0 0 0" rpy="${M_PI/2} 0 0" />
        <geometry>
          <cylinder length="${wheel_length}" radius="${wheel_radius}" />
        </geometry>
      </collision> 
    </link>

  <xacro:if value="${is_sim}">
      <joint name="${wheel_prefix}_wheel_joint" type="continuous">
      <parent link="base_link"/>
      <child link="${wheel_prefix}_wheel"/>
      <origin xyz="${x} ${y} ${z}" rpy="${roll} ${pitch} ${yaw}"/>
      <axis xyz="0 1 0" rpy="0 0 0" />
    </joint>
    <gazebo reference="${wheel_prefix}_wheel">
      <mu1 value="1.0"/>
      <mu2 value="0.5"/>
      <kp value="10000000.0" />
      <kd value="1.0" />
      <fdir1 value="1 0 0"/>
    </gazebo>
  </xacro:if>

  <xacro:unless value="${is_sim}">
    <joint name="${wheel_prefix}_wheel_joint" type="fixed">
      <parent link="base_link"/>
      <child link="${wheel_prefix}_wheel"/>
      <origin xyz="${x} ${y} ${z}" rpy="${roll} ${pitch} ${yaw}"/>
      <axis xyz="0 1 0" rpy="0 0 0" />
    </joint>
  </xacro:unless>

  </xacro:macro>
</robot>